using System;
using System.Console;

class AException : Exception
{

}

class aException : Exception
{

}

module Program
{

  Main() : void
  {
    try
    {
      WriteLine("test exception");
      throw ArgumentException();
    }
    catch
    {
      | ArgumentException => WriteLine("Ok")
    }
    try
    {
      WriteLine("test exception2");
      throw aException();
    }
    catch
    {
      | _ is aException   => WriteLine("Ok")
      | argumentException => WriteLine("Fail") // W: N168: a caught exception argumentException was never used \(defined in 'Main\(\) : void'\)
      | ex                => WriteLine("Fail") // W: N168: a caught exception ex was never used \(defined in 'Main\(\) : void'\)
    }
    try
    {
      WriteLine("test exception3");
      throw AException();
    }
    catch
    {
      | AException => WriteLine("Ok")
      | _          => WriteLine("Fail")
    }
  }
}


/*
BEGIN-OUTPUT
test exception
Ok
test exception2
Ok
test exception3
Ok
END-OUTPUT
*/
